Workbook
Name Slicer_Country: #N/A
Name Slicer_Country_Code1: #N/A

Sheet Trend Analysis Dashboard
E5: Financial Inclusion Level | I5: E-Government Level | K5: Internet Penetration Level | O5: Digital Payments Level
F6: =IF(COUNTIF('Trend Analysis'!A91:A95,"*") >1,0,'Trend Analysis'!L119) -> 0 | I6: =IF(COUNTIF('Trend Analysis'!A91:A95,"*") >1,0,'Trend Analysis'!D91) -> 0 | L6: =IF(COUNTIF('Trend Analysis'!A91:A95,"*") > 1,0,'Trend Analysis'!E91) -> 0 | O6: =IF(COUNTIF('Trend Analysis'!A91:A95,"*") >1,0,'Trend Analysis'!F91) -> 0

Sheet DT IndicatorsAnalysis Dashboard
F5: E-Government Level | J5: Internet Penetration Level | N5: Digital Payments Level
G6: =IF(COUNTIF('DT Components Analysis'!A87:A91,"*") >1,0,'DT Components Analysis'!B87) -> 0 | J6: =IF(COUNTIF('DT Components Analysis'!A95:A99,"*") >1,0,'DT Components Analysis'!B95) -> 0 | N6: =IF(COUNTIF('DT Components Analysis'!A103:A107,"*") >1,0,'DT Components Analysis'!B103) -> 0

Sheet Impact Analysis Dashboard
C5: Digital Transformation Level | G5: Financoal Inclusion Level | K5: Digital Transformaion Growth | O5: Financial Inclusion Growth | R5: Main Driver of Financial
D6: =IF(COUNTIF('Impact Analysis'!B77:B81,"*") >1,0,'Impact Analysis'!C77) -> 0 | G6: =IF(COUNTIF('Impact Analysis'!B77:B81,"*") >1,0,'Impact Analysis'!D77) -> 0 | K6: =IF(COUNTIF('Impact Analysis'!B88:B92,"*") >1,0,'Impact Analysis'!M88) -> 0 | O6: =IF(COUNTIF('Impact Analysis'!B98:B102,"*") >1,0,'Impact Analysis'!M98) -> 0 | S6: E-Governemt

Sheet Growth Analysis Dashboard
C5: Digital Transformation Growth% | G5: Financial Inclusion Growth% | K5: E-Governmet Growth% | N5: Internet Growth% | Q5: Digital Payments Growth%
D6: =IF(COUNTIF('Growth Analysis'!A79:A83,"*") >1,0,'Growth Analysis'!B79) -> 0 | H6: =IF(COUNTIF('Growth Analysis'!A79:A83,"*") >1,0,'Growth Analysis'!C79) -> 0 | K6: =IF(COUNTIF('Growth Analysis'!A79:A83,"*") >1,0,'Growth Analysis'!D79) -> 0 | O6: =IF(COUNTIF('Growth Analysis'!A79:A83,"*") >1,0,'Growth Analysis'!E79) -> 0 | Q6: =IF(COUNTIF('Growth Analysis'!A79:A83,"*") >1,0,'Growth Analysis'!F79) -> 0

Sheet Trend Analysis
A1: KPI`s
B2: DT Growth
A6: Q1:- How has E-Government evolved over time?
A10: AVG E_GOV_Index | B10: Column Labels
A11: Row Labels | B11: Egypt, Arab Rep | C11: India | D11: Saudi Arabia | E11: United Arab Emirates | F11: United Kingdom
A12: 2015
A13: 2016 | B13: 0.45941 | C13: 0.46375 | D13: 0.68223667 | E13: 0.75153 | F13: 0.91928
A14: 2017
A15: 2018 | B15: 0.48803333 | C15: 0.5669 | D15: 0.7119 | E15: 0.8295 | F15: 0.89986667
A16: 2019
A17: 2020 | B17: 0.5527 | C17: 0.5964 | D17: 0.79906667 | E17: 0.85546667 | F17: 0.93583333
A18: 2021
A19: 2022 | B19: 0.58946667 | C19: 0.5883 | D19: 0.8539 | E19: 0.90103333 | F19: 0.9138
A20: 2023
A21: 2024 | B21: 0.66991667 | C21: 0.66777667 | D21: 0.96024 | E21: 0.95327333 | F21: 0.95771333
A27: Q2:- How has Internet penetration changed over time?
A29: Average of Internet_All_Index | B29: Column Labels
A30: Row Labels | B30: Egypt, Arab Rep | C30: India | D30: Saudi Arabia | E30: United Arab Emirates | F30: United Kingdom
A31: 2015 | B31: 0.39615536 | C31: 0.071035104 | D31: 0.61190945 | E31: 0.67705505 | F31: 0.83328054
A32: 2016 | B32: 0.47174173 | C32: 0.077897119 | D32: 0.65753362 | E32: 0.70530673 | F32: 0.84992643
A33: 2017 | B33: 0.53624185 | C33: 0.052823426 | D33: 0.66175924 | E33: 0.78010321 | F33: 0.80547826
A34: 2018 | B34: 0.42333061 | C34: 0.34930449 | D34: 0.70653109 | E34: 0.79304168 | F34: 0.80291156
A35: 2019 | B35: 0.30304256 | C35: 0.26480193 | D35: 0.50821066 | E35: 0.59675259 | F35: 0.57618978
A36: 2020 | B36: 0.3288001 | C36: 0.25976405 | D36: 0.53791687 | E36: 0.73536569 | F36: 0.57077825
A37: 2021 | B37: 0.34016809 | C37: 0.30331355 | D37: 0.55881088 | E37: 0.85655199 | F37: 0.64291908
A38: 2022 | B38: 0.35560602 | C38: 0.33933878 | D38: 0.56067211 | E38: 0.81785874 | F38: 0.67430668
A39: 2023 | B39: 0.38245537 | C39: 0.41050434 | D39: 0.64747935 | E39: 0.89159616 | F39: 0.70395887
A40: 2024 | B40: 0.39942629 | C40: 0.43199623 | D40: 0.75154042 | E40: 0.95780394 | F40: 0.73587031
A45: Q3:-How have Digital Payments evolved?
A47: Average of Digital_Payments_Index | B47: Column Labels
A48: Row Labels | B48: Egypt, Arab Rep | C48: India | D48: Saudi Arabia | E48: United Arab Emirates | F48: United Kingdom
A49: 2015
A50: 2016
A51: 2017 | B51: 0.016683175 | C51: 0.039786186 | D51: 0.4149803 | E51: 0.67466197 | F51: 0.65162195
A52: 2018
A53: 2019
A54: 2020
A55: 2021 | B55: 0.016183336 | C55: 0.17220947 | D55: 0.7504119 | E55: 0.45407507 | F55: 0.61909372
A56: 2022
A57: 2023
...

Sheet DT Components Analysis
A2: Q1:- How Does E-Government differ across countries?
A3: Row Labels | B3: Average of E_GOV_Index
A4: United Kingdom | B4: 0.92529867
A5: United Arab Emirates | B5: 0.85816067
A6: Saudi Arabia | B6: 0.80146867
A7: India | B7: 0.57662533
A8: Egypt, Arab Rep | B8: 0.55190533
A19: Row Labels | B19: Average of Digital_Payments_Index
A20: Saudi Arabia | B20: 0.67231857
A21: United Kingdom | B21: 0.63535783
A22: United Arab Emirates | B22: 0.56436852
A23: India | B23: 0.2326286
A24: Egypt, Arab Rep | B24: 0.1113356
A27: Q2:- What are the key digital Trnasformationstrenghts of each country?
A29: Row Labels | B29: Avg Internet Index
A30: United Arab Emirates | B30: 0.78114358
A31: United Kingdom | B31: 0.71956198
A32: Saudi Arabia | B32: 0.62023637
A33: Egypt, Arab Rep | B33: 0.3936968
A34: India | B34: 0.2560779
A48: Q3:-Which Countries is the overall Digital transformation Leader?
A50: Row Labels | B50: Average of Digital_Transformation_Index
A51: United Arab Emirates | B51: 0.769819
A52: United Kingdom | B52: 0.7603129
A53: Saudi Arabia | B53: 0.65699071
A54: Egypt, Arab Rep | B54: 0.38276635
A55: India | B55: 0.31797892
A66: What is the Current Performance of the Selected Country?
A67: 1- مستوى التحول الرقمى العام في الدولة
A68: Country | B68: Average of Digital_Transformation_Index | C68: Digital_Transformation_Level
A69: United Kingdom | B69: 0.7603129
A70: United Arab Emirates | B70: 0.769819
A71: Saudi Arabia | B71: 0.65699071
A72: India | B72: 0.31797892
A73: Egypt, Arab Rep | B73: 0.38276635
A77: 2- مدى الشمول المالى في كل دولة
A78: Row Labels | B78: Average of FI_All_Index | C78: Financial_Inclusion_Level
A79: United Kingdom | B79: 0.96138277
A80: United Arab Emirates | B80: 0.59536357
A81: Saudi Arabia | B81: 0.52411387
...

Sheet Impact Analysis
A2: Q1:- Does Internet Penetration drive Impact on Financial Inclusion?
A3: Country | B3: Average of Internet_All_Index | C3: Average of FI_All_Index
A4: United Kingdom | B4: 0.71956198 | C4: 0.96138277
A5: United Arab Emirates | B5: 0.78114358 | C5: 0.59536357
A6: Saudi Arabia | B6: 0.62023637 | C6: 0.52411387
A7: India | B7: 0.2560779 | C7: 0.45949314 | J7: Country | K7: Average of E_GOV_Index | L7: Average of FI_All_Index
A8: Egypt, Arab Rep | B8: 0.40111483 | C8: 0.048929877 | J8: United Kingdom | K8: 0.92529867 | L8: 0.96138277
J9: United Arab Emirates | K9: 0.85816067 | L9: 0.59536357
J10: Saudi Arabia | K10: 0.80146867 | L10: 0.52411387
J11: India | K11: 0.57662533 | L11: 0.45949314
J12: Egypt, Arab Rep | K12: 0.55190533 | L12: 0.06340562
A20: Q1:- Does E-Governemt impact on Financial Inclusion? | J20: Country | K20: Average of Digital_Payments_Index | L20: Average of FI_All_Index
A21: Country | B21: Average of E_GOV_Index | C21: Average of FI_All_Index | J21: United Kingdom | K21: 0.63535783 | L21: 0.96138277
A22: United Kingdom | B22: 0.92529867 | C22: 0.96138277 | J22: United Arab Emirates | K22: 0.56436852 | L22: 0.59536357
A23: United Arab Emirates | B23: 0.85816067 | C23: 0.59536357 | J23: Saudi Arabia | K23: 0.67231857 | L23: 0.52411387
A24: Saudi Arabia | B24: 0.80146867 | C24: 0.52411387 | J24: India | K24: 0.2326286 | L24: 0.45949314
A25: India | B25: 0.57662533 | C25: 0.45949314 | J25: Egypt, Arab Rep | K25: 0.1113356 | L25: 0.06340562
A26: Egypt, Arab Rep | B26: 0.55190533 | C26: 0.048929877
A38: Q3:- Is Digital Transformation linked to Financial Inclusion?
A39: Country | B39: Average of Digital_Transformation_Index | C39: Average of FI_All_Index
A40: United Kingdom | B40: 0.77908653 | C40: 0.96138277
A41: United Arab Emirates | B41: 0.76342003 | C41: 0.59536357
A42: Saudi Arabia | B42: 0.64331314 | C42: 0.52411387
A43: India | B43: 0.33673315 | C43: 0.45949314
A44: Egypt, Arab Rep | B44: 0.32720017 | C44: 0.048929877
A58: Q3:- Is Digital Payments linked to Financial Inclusion?
A60: Country | B60: Average of Digital_Payments_Index | C60: Average of FI_All_Index
A61: United Kingdom | B61: 0.63535783 | C61: 0.96138277
A62: United Arab Emirates | B62: 0.56436852 | C62: 0.59536357
A63: Saudi Arabia | B63: 0.67231857 | C63: 0.52411387
A64: India | B64: 0.2326286 | C64: 0.45949314
A65: Egypt, Arab Rep | B65: 0.1113356 | C65: 0.06340562
B69: KPIs
B70: Digital Transformation Level
B71: Financial Inclusion Level
B72: Digital Transformation Growth
B73: Financial Inclusion Gross
B74: Main Digital Driver
B76: Country | C76: Average of Digital_Transformation_Index | D76: Average of FI_All_Index | E76: Average of E_GOV_Index | F76: Average of Internet_All_Index | G76: Average of Digital_Payments_Index
B77: United Kingdom | C77: 0.7603129 | D77: 0.96138277 | E77: 0.92529867 | F77: 0.71956198 | G77: 0.63535783
...

Sheet Growth Analysis
A5: Which Digital transformation Indicators and financial inclusion have grown the fastest over time?
A7: KPI`s
A8: Digital Transformation Growth
A9: Financial Inclusion Growth
A10: E-Government Growth
A11: Digital _Payments Growth
A12: Internet Growth
A15: 1- Digital Transformation Growth
A17: Average of Digital_Transformation_Index | B17: Year
A18: Country | B18: 2015 | C18: 2016 | D18: 2017 | E18: 2018 | F18: 2019 | G18: 2020 | H18: 2021 | I18: 2022 | J18: 2023 | K18: 2024 | L18: DT_Growth%
A19: United Kingdom | B19: 0.83328054 | C19: 0.88460322 | D19: 0.72855011 | E19: 0.85138911 | F19: 0.57618978 | G19: 0.75330579 | H19: 0.6310064 | I19: 0.79405334 | J19: 0.70395887 | K19: 0.84679182 | L19: =(AVERAGE(H19:K19) - AVERAGE(B19:E19)) / AVERAGE(B19:E19) * 100 -> -9.7643972
A20: United Arab Emirates | B20: 0.67705505 | C20: 0.72841837 | D20: 0.72738259 | E20: 0.81127084 | F20: 0.59675259 | G20: 0.79541618 | H20: 0.65531353 | I20: 0.85944604 | J20: 0.89159616 | K20: 0.95553864 | L20: =(AVERAGE(H20:K20) - AVERAGE(B20:E20)) / AVERAGE(B20:E20) * 100 -> 14.189861
A21: Saudi Arabia | B21: 0.61190945 | C21: 0.66988514 | D21: 0.53836977 | E21: 0.70921554 | F21: 0.50821066 | G21: 0.66849177 | H21: 0.65461139 | I21: 0.70728605 | J21: 0.64747935 | K21: 0.85444798 | L21: =(AVERAGE(H21:K21) - AVERAGE(B21:E21)) / AVERAGE(B21:E21) * 100 -> 13.222405
A22: India | B22: 0.071035104 | C22: 0.27082356 | D22: 0.046304806 | E22: 0.45810224 | F22: 0.26480193 | G22: 0.42808202 | H22: 0.23776151 | I22: 0.46381939 | J22: 0.41050434 | K22: 0.52855434 | L22: =(AVERAGE(H22:K22) - AVERAGE(B22:E22)) / AVERAGE(B22:E22) * 100 -> 93.868138
A23: Egypt, Arab Rep | B23: 0.39615536 | C23: 0.46557586 | D23: 0.27646252 | E23: 0.45568197 | F23: 0.30304256 | G23: 0.44075005 | H23: 0.17817571 | I23: 0.47253634 | J23: 0.38245537 | K23: 0.45682775 | L23: =(AVERAGE(H23:K23) - AVERAGE(B23:E23)) / AVERAGE(B23:E23) * 100 -> -6.5174801
A26: 2 - Financial Inclusion Growth
A27: Average of FI_All_Index | B27: Year
A28: Country | B28: 2015 | C28: 2016 | D28: 2017 | E28: 2018 | F28: 2019 | G28: 2020 | H28: 2021 | I28: 2022 | J28: 2023 | K28: 2024 | L28: FI_Growth%
A29: United Kingdom | D29: 0.97651418 | H29: 0.94625136 | L29: =IF(OR(ISBLANK(K29), K29 = 0), H29-D29, K29-D29) / D29 * 100 -> -3.0990654
A30: United Arab Emirates | D30: 0.69352779 | H30: 0.49719936 | L30: =IF(OR(ISBLANK(K30), K30 = 0), H30-D30, K30-D30) / D30 * 100 -> -28.308661
A31: Saudi Arabia | D31: 0.4107756 | H31: 0.56615915 | K31: 0.59540687 | L31: =IF(OR(ISBLANK(K31), K31 = 0), H31-D31, K31-D31) / D31 * 100 -> 44.94699
A32: India | D32: 0.43294952 | H32: 0.40404787 | K32: 0.54148204 | L32: =IF(OR(ISBLANK(K32), K32 = 0), H32-D32, K32-D32) / D32 * 100 -> 25.068169
A33: Egypt, Arab Rep | D33: 0.054432523 | H33: 0 | K33: 0.13578434 | L33: =IF(OR(ISBLANK(K33), K33 = 0), H33-D33, K33-D33) / D33 * 100 -> 149.45442
A36: 3 - E-Government Growth
A37: Average of E_GOV_Index | B37: Year
A38: Country | B38: 2015 | C38: 2016 | D38: 2017 | E38: 2018 | F38: 2019 | G38: 2020 | H38: 2021 | I38: 2022 | J38: 2023 | K38: 2024 | L38: EGOV_Growth%
A39: United Kingdom | C39: 0.91928 | E39: 0.89986667 | G39: 0.93583333 | I39: 0.9138 | K39: 0.95771333 | L39: =(AVERAGE(K39,I39) - AVERAGE(E39,C39)) / AVERAGE(E39,C39) * 100 -> 2.8786391
A40: United Arab Emirates | C40: 0.75153 | E40: 0.8295 | G40: 0.85546667 | I40: 0.90103333 | K40: 0.95327333 | L40: =(AVERAGE(K40,I40) - AVERAGE(E40,C40)) / AVERAGE(E40,C40) * 100 -> 17.284724
A41: Saudi Arabia | C41: 0.68223667 | E41: 0.7119 | G41: 0.79906667 | I41: 0.8539 | K41: 0.96024 | L41: =(AVERAGE(K41,I41) - AVERAGE(E41,C41)) / AVERAGE(E41,C41) * 100 -> 30.12641
A42: India | C42: 0.46375 | E42: 0.5669 | G42: 0.5964 | I42: 0.5883 | K42: 0.66777667 | L42: =(AVERAGE(K42,I42) - AVERAGE(E42,C42)) / AVERAGE(E42,C42) * 100 -> 21.872281
A43: Egypt, Arab Rep | C43: 0.45941 | E43: 0.48803333 | G43: 0.5527 | I43: 0.58946667 | K43: 0.66991667 | L43: =(AVERAGE(K43,I43) - AVERAGE(E43,C43)) / AVERAGE(E43,C43) * 100 -> 32.924397
A47: 4 - Digital _Payments Growth
A48: Average of Digital_Payments_Index | B48: Year
A49: Country | B49: 2015 | C49: 2016 | D49: 2017 | E49: 2018 | F49: 2019 | G49: 2020 | H49: 2021 | I49: 2022 | J49: 2023 | K49: 2024 | L49: Digital _Payments Growth%
A50: United Kingdom | D50: 0.65162195 | H50: 0.61909372 | L50: =IF(OR(ISBLANK(K50), K50 = 0), H50-D50, K50-D50) / D50 * 100 -> -4.9918873
A51: United Arab Emirates | D51: 0.67466197 | H51: 0.45407507 | L51: =IF(OR(ISBLANK(K51), K51 = 0), H51-D51, K51-D51) / D51 * 100 -> -32.695914
A52: Saudi Arabia | D52: 0.4149803 | H52: 0.7504119 | K52: 0.85156351 | L52: =IF(OR(ISBLANK(K52), K52 = 0), H52-D52, K52-D52) / D52 * 100 -> 105.20577
A53: India | D53: 0.039786186 | H53: 0.17220947 | K53: 0.48589013 | L53: =IF(OR(ISBLANK(K53), K53 = 0), H53-D53, K53-D53) / D53 * 100 -> 1121.2533
A54: Egypt, Arab Rep | D54: 0.016683175 | H54: 0.016183336 | K54: 0.30114029 | L54: =IF(OR(ISBLANK(K54), K54 = 0), H54-D54, K54-D54) / D54 * 100 -> 1705.0538
A58: 5 - Internet Penetration Growth
...

Sheet Fact_Digital_Transformation_Ind
A1: Code_ID | B1: Country_Code | C1: Country | D1: Year | E1: Internet_Access_Index | F1: Internet_Affordability_Index | G1: Internet_Quality_Index | H1: Internet_All_Index | I1: EGDI_Rank | J1: OSI_Value | K1: TII_Value | L1: HCI_Value | M1: EPI_Value | N1: EPI_Rank | O1: E_GOV_Index | P1: Digital_Payments_Index | Q1: FI_Access_Index | R1: FI_Usage_Index | S1: FI_All_Index | T1: Digital_Tranformation_Index
A2: EGY_2015 | B2: EGY | C2: Egypt, Arab Rep | D2: 2015 | E2: 0.16126787 | F2: 0.63104284 | H2: 0.39615536 | T2: 0.39615536
A3: EGY_2024 | B3: EGY | C3: Egypt, Arab Rep | D3: 2024 | E3: 0.42545458 | F3: 0.71060744 | G3: 0.062216847 | H3: 0.39942629 | I3: 95 | J3: 0.70016 | K3: 0.69456 | L3: 0.61503 | M3: 0.589 | N3: 74 | O3: 0.66991667 | P3: 0.30114029 | Q3: 0.21667021 | R3: 0.054898463 | S3: 0.13578434 | T3: 0.45682775
A4: SAU_2019 | B4: SAU | C4: Saudi Arabia | D4: 2019 | E4: 0.62501754 | F4: 0.80625401 | G4: 0.093360433 | H4: 0.50821066 | T4: 0.50821066
A5: SAU_2017 | B5: SAU | C5: Saudi Arabia | D5: 2017 | E5: 0.55801265 | F5: 0.76550583 | H5: 0.66175924 | P5: 0.4149803 | Q5: 0.61192697 | R5: 0.20962423 | S5: 0.4107756 | T5: 0.53836977
A6: EGY_2022 | B6: EGY | C6: Egypt, Arab Rep | D6: 2022 | E6: 0.38753152 | F6: 0.64246725 | G6: 0.036819293 | H6: 0.35560602 | I6: 103 | J6: 0.573 | K6: 0.5579 | L6: 0.6375 | M6: 0.3523 | N6: 107 | O6: 0.58946667 | T6: 0.47253634
A7: SAU_2015 | B7: SAU | C7: Saudi Arabia | D7: 2015 | E7: 0.42887841 | F7: 0.79494048 | H7: 0.61190945 | T7: 0.61190945
A8: EGY_2020 | B8: EGY | C8: Egypt, Arab Rep | D8: 2020 | E8: 0.36362809 | F8: 0.59955209 | G8: 0.023220114 | H8: 0.3288001 | I8: 111 | J8: 0.5706 | K8: 0.4683 | L8: 0.6192 | M8: 0.5119 | N8: 106 | O8: 0.5527 | T8: 0.44075005
A9: SAU_2020 | B9: SAU | C9: Saudi Arabia | D9: 2020 | E9: 0.69565987 | F9: 0.67317733 | G9: 0.24491342 | H9: 0.53791687 | I9: 43 | J9: 0.6882 | K9: 0.8442 | L9: 0.8648 | M9: 0.7143 | N9: 66 | O9: 0.79906667 | T9: 0.66849177
A10: SAU_2021 | B10: SAU | C10: Saudi Arabia | D10: 2021 | E10: 0.77887701 | F10: 0.57805622 | G10: 0.3194994 | H10: 0.55881088 | P10: 0.7504119 | Q10: 0.64819158 | R10: 0.48412671 | S10: 0.56615915 | T10: 0.65461139
A11: EGY_2018 | B11: EGY | C11: Egypt, Arab Rep | D11: 2018 | E11: 0.22934967 | F11: 0.61731154 | H11: 0.42333061 | I11: 114 | J11: 0.5347 | K11: 0.3222 | L11: 0.6072 | M11: 0.5393 | N11: 109 | O11: 0.48803333 | T11: 0.45568197
A12: SAU_2016 | B12: SAU | C12: Saudi Arabia | D12: 2016 | E12: 0.44257539 | F12: 0.87249184 | H12: 0.65753362 | I12: 44 | J12: 0.67391 | K12: 0.57334 | L12: 0.79946 | M12: 0.71186 | N12: 39 | O12: 0.68223667 | T12: 0.66988514
A13: EGY_2016 | B13: EGY | C13: Egypt, Arab Rep | D13: 2016 | E13: 0.18249398 | F13: 0.76098947 | H13: 0.47174173 | I13: 108 | J13: 0.47101 | K13: 0.30246 | L13: 0.60476 | M13: 0.40678 | N13: 107 | O13: 0.45941 | T13: 0.46557586
A14: SAU_2022 | B14: SAU | C14: Saudi Arabia | D14: 2022 | E14: 0.84988537 | F14: 0.48788688 | G14: 0.34424407 | H14: 0.56067211 | I14: 31 | J14: 0.822 | K14: 0.8735 | L14: 0.8662 | M14: 0.6932 | N14: 43 | O14: 0.8539 | T14: 0.70728605
A15: IND_2020 | B15: IND | C15: India | D15: 2020 | E15: 0.18714871 | F15: 0.52288801 | G15: 0.069255422 | H15: 0.25976405 | I15: 100 | J15: 0.8529 | K15: 0.3515 | L15: 0.5848 | M15: 0.8571 | N15: 29 | O15: 0.5964 | T15: 0.42808202
A16: SAU_2023 | B16: SAU | C16: Saudi Arabia | D16: 2023 | E16: 0.90307143 | F16: 0.67802175 | G16: 0.36134486 | H16: 0.64747935 | T16: 0.64747935
A17: IND_2016 | B17: IND | C17: India | D17: 2016 | E17: 0.019298221 | F17: 0.13649602 | H17: 0.077897119 | I17: 107 | J17: 0.74638 | K17: 0.14298 | L17: 0.50189 | M17: 0.76271 | N17: 27 | O17: 0.46375 | T17: 0.27082356
A18: SAU_2018 | B18: SAU | C18: Saudi Arabia | D18: 2018 | E18: 0.60680817 | F18: 0.80625401 | H18: 0.70653109 | I18: 52 | J18: 0.7917 | K18: 0.5339 | L18: 0.8101 | M18: 0.7135 | N18: 67 | O18: 0.7119 | T18: 0.70921554
A19: SAU_2024 | B19: SAU | C19: Saudi Arabia | D19: 2024 | E19: 0.92829314 | F19: 0.92843244 | G19: 0.39789567 | H19: 0.75154042 | I19: 6 | J19: 0.98995 | K19: 0.98411 | L19: 0.90666 | M19: 0.9589 | N19: 7 | O19: 0.96024 | P19: 0.85156351 | Q19: 0.71069505 | R19: 0.48011869 | S19: 0.59540687 | T19: 0.85444798
A20: EGY_2017 | B20: EGY | C20: Egypt, Arab Rep | D20: 2017 | E20: 0.20666909 | F20: 0.86581462 | H20: 0.53624185 | P20: 0.016683175 | Q20: 0.073844151 | R20: 0.035020895 | S20: 0.054432523 | T20: 0.27646252
A21: EGY_2017 | B21: EGY | C21: Egypt, Arab Rep | D21: 2017 | E21: 0.20666909 | F21: 0.86581462 | H21: 0.53624185 | P21: 0 | Q21: 0.073844151 | R21: 0.035020895 | S21: 0.054432523 | T21: 0.26812093
A22: IND_2019 | B22: IND | C22: India | D22: 2019 | E22: 0.12153213 | F22: 0.63735352 | G22: 0.035520131 | H22: 0.26480193 | T22: 0.26480193
A23: EGY_2019 | B23: EGY | C23: Egypt, Arab Rep | D23: 2019 | E23: 0.28513627 | F23: 0.61731154 | G23: 0.0066798628 | H23: 0.30304256 | T23: 0.30304256
A24: EGY_2021 | B24: EGY | C24: Egypt, Arab Rep | D24: 2021 | E24: 0.37345019 | F24: 0.6130747 | G24: 0.033979383 | H24: 0.34016809 | P24: 0.016183336 | Q24: 0 | R24: 0 | S24: 0 | T24: 0.17817571
A25: EGY_2021 | B25: EGY | C25: Egypt, Arab Rep | D25: 2021 | E25: 0.37345019 | F25: 0.6130747 | G25: 0.033979383 | H25: 0.34016809 | P25: 0.0063614991 | Q25: 0 | R25: 0 | S25: 0 | T25: 0.17326479
A26: EGY_2023 | B26: EGY | C26: Egypt, Arab Rep | D26: 2023 | E26: 0.39983578 | F26: 0.70078574 | G26: 0.046744579 | H26: 0.38245537 | T26: 0.38245537
A27: IND_2015 | B27: IND | C27: India | D27: 2015 | E27: 0 | F27: 0.14207021 | H27: 0.071035104 | T27: 0.071035104
A28: GBR_2015 | B28: GBR | C28: United Kingdom | D28: 2015 | E28: 0.70196602 | F28: 0.96459505 | H28: 0.83328054 | T28: 0.83328054
A29: GBR_2016 | B29: GBR | C29: United Kingdom | D29: 2016 | E29: 0.71790963 | F29: 0.98194323 | H29: 0.84992643 | I29: 1 | J29: 1 | K29: 0.81766 | L29: 0.94018 | M29: 1 | N29: 1 | O29: 0.91928 | T29: 0.88460322
A30: IND_2017 | B30: IND | C30: India | D30: 2017 | E30: 0.041052588 | F30: 0.064594265 | H30: 0.052823426 | P30: 0.039786186 | Q30: 0.72499797 | R30: 0.14090107 | S30: 0.43294952 | T30: 0.046304806
A31: GBR_2019 | B31: GBR | C31: United Kingdom | D31: 2019 | E31: 0.75742641 | F31: 0.8554698 | G31: 0.11567314 | H31: 0.57618978 | T31: 0.57618978
A32: GBR_2017 | B32: GBR | C32: United Kingdom | D32: 2017 | E32: 0.71336343 | F32: 0.89759309 | H32: 0.80547826 | P32: 0.65162195 | Q32: 0.95302836 | R32: 1 | S32: 0.97651418 | T32: 0.72855011
A33: IND_2018 | B33: IND | C33: India | D33: 2018 | E33: 0.068116664 | F33: 0.63049231 | H33: 0.34930449 | I33: 96 | J33: 0.9514 | K33: 0.2009 | L33: 0.5484 | M33: 0.9551 | N33: 15 | O33: 0.5669 | T33: 0.45810224
A34: GBR_2018 | B34: GBR | C34: United Kingdom | D34: 2018 | E34: 0.73962884 | F34: 0.86619429 | H34: 0.80291156 | I34: 4 | J34: 0.9792 | K34: 0.8004 | L34: 0.92 | M34: 0.9831 | N34: 5 | O34: 0.89986667 | T34: 0.85138911
A35: GBR_2020 | B35: GBR | C35: United Kingdom | D35: 2020 | E35: 0.77705178 | F35: 0.78692744 | G35: 0.14835553 | H35: 0.57077825 | I35: 7 | J35: 0.9588 | K35: 0.9195 | L35: 0.9292 | M35: 0.9762 | N35: 6 | O35: 0.93583333 | T35: 0.75330579
A36: IND_2021 | B36: IND | C36: India | D36: 2021 | E36: 0.21653733 | F36: 0.57675243 | G36: 0.11665089 | H36: 0.30331355 | P36: 0.17220947 | Q36: 0.69255584 | R36: 0.1155399 | S36: 0.40404787 | T36: 0.23776151
A37: GBR_2021 | B37: GBR | C37: United Kingdom | D37: 2021 | E37: 0.81470211 | F37: 0.88137903 | G37: 0.2326761 | H37: 0.64291908 | P37: 0.61909372 | Q37: 1 | R37: 0.89250273 | S37: 0.94625136 | T37: 0.6310064
A38: IND_2022 | B38: IND | C38: India | D38: 2022 | E38: 0.24904889 | F38: 0.62886795 | G38: 0.14009948 | H38: 0.33933878 | I38: 105 | J38: 0.7934 | K38: 0.3954 | L38: 0.5761 | M38: 0.5909 | N38: 61 | O38: 0.5883 | T38: 0.46381939
A39: GBR_2022 | B39: GBR | C39: United Kingdom | D39: 2022 | E39: 0.81976665 | F39: 0.89883675 | G39: 0.30431665 | H39: 0.67430668 | I39: 11 | J39: 0.8859 | K39: 0.9186 | L39: 0.9369 | M39: 0.9545 | N39: 6 | O39: 0.9138 | T39: 0.79405334
A40: IND_2023 | B40: IND | C40: India | D40: 2023 | E40: 0.27622618 | F40: 0.62471784 | G40: 0.33056899 | H40: 0.41050434 | T40: 0.41050434
...

Sheet Financial_Index_Data_Cleaned1
A1: Code_ID | B1: Country_Code | C1: Country | D1: Year | E1: Access_Index | F1: Usage_Index | G1: FI_Index
A2: EGY_2017 | B2: EGY | C2: Egypt, Arab Rep | D2: 2017 | E2: 0.073844151 | F2: 0.035020895 | G2: 0.054432523
A3: IND_2017 | B3: IND | C3: India | D3: 2017 | E3: 0.72499797 | F3: 0.14090107 | G3: 0.43294952
A4: SAU_2017 | B4: SAU | C4: Saudi Arabia | D4: 2017 | E4: 0.61192697 | F4: 0.20962423 | G4: 0.4107756
A5: ARE_2017 | B5: ARE | C5: United Arab Emirates | D5: 2017 | E5: 0.84025166 | F5: 0.54680391 | G5: 0.69352779
A6: GBR_2017 | B6: GBR | C6: United Kingdom | D6: 2017 | E6: 0.95302836 | F6: 1 | G6: 0.97651418
A7: EGY_2021 | B7: EGY | C7: Egypt, Arab Rep | D7: 2021 | E7: 0 | F7: 0 | G7: 0
A8: IND_2021 | B8: IND | C8: India | D8: 2021 | E8: 0.69255584 | F8: 0.1155399 | G8: 0.40404787
A9: SAU_2021 | B9: SAU | C9: Saudi Arabia | D9: 2021 | E9: 0.64819158 | F9: 0.48412671 | G9: 0.56615915
A10: ARE_2021 | B10: ARE | C10: United Arab Emirates | D10: 2021 | E10: 0.80612247 | F10: 0.18827624 | G10: 0.49719936
A11: GBR_2021 | B11: GBR | C11: United Kingdom | D11: 2021 | E11: 1 | F11: 0.89250273 | G11: 0.94625136
A12: EGY_2024 | B12: EGY | C12: Egypt, Arab Rep | D12: 2024 | E12: 0.21667021 | F12: 0.054898463 | G12: 0.13578434
A13: IND_2024 | B13: IND | C13: India | D13: 2024 | E13: 0.85151327 | F13: 0.2314508 | G13: 0.54148204
A14: SAU_2024 | B14: SAU | C14: Saudi Arabia | D14: 2024 | E14: 0.71069505 | F14: 0.48011869 | G14: 0.59540687

Sheet Digital_Payments_Index1
A1: Code_ID | B1: Country_Code | C1: Country | D1: Year | E1: Digital_Payments_Index
A2: EGY_2017 | B2: EGY | C2: Egypt, Arab Rep | D2: 2017 | E2: 0.016683175
A3: IND_2017 | B3: IND | C3: India | D3: 2017 | E3: 0.039786186
A4: SAU_2017 | B4: SAU | C4: Saudi Arabia | D4: 2017 | E4: 0.4149803
A5: ARE_2017 | B5: ARE | C5: United Arab Emirates | D5: 2017 | E5: 0.67466197
A6: GBR_2017 | B6: GBR | C6: United Kingdom | D6: 2017 | E6: 0.65162195
A7: EGY_2021 | B7: EGY | C7: Egypt, Arab Rep | D7: 2021 | E7: 0.016183336
A8: IND_2021 | B8: IND | C8: India | D8: 2021 | E8: 0.17220947
A9: SAU_2021 | B9: SAU | C9: Saudi Arabia | D9: 2021 | E9: 0.7504119
A10: ARE_2021 | B10: ARE | C10: United Arab Emirates | D10: 2021 | E10: 0.45407507
A11: GBR_2021 | B11: GBR | C11: United Kingdom | D11: 2021 | E11: 0.61909372
A12: EGY_2024 | B12: EGY | C12: Egypt, Arab Rep | D12: 2024 | E12: 0.30114029
A13: IND_2024 | B13: IND | C13: India | D13: 2024 | E13: 0.48589013
A14: SAU_2024 | B14: SAU | C14: Saudi Arabia | D14: 2024 | E14: 0.85156351
A15: GBR_2024 | B15: GBR | C15: United Kingdom | D15: 2024
A16: EGY_2017 | B16: EGY | C16: Egypt, Arab Rep | D16: 2017 | E16: 0
A17: EGY_2021 | B17: EGY | C17: Egypt, Arab Rep | D17: 2021 | E17: 0.0063614991

Sheet EGOV_Index_DATA_Cleaned1
A1: Code_ID | B1: Country_Code | C1: Country | D1: Year | E1: EGDI_Rank | F1: OSI_Value | G1: TII_Value | H1: HCI_Value | I1: EPI_Value | J1: EPI_Rank | K1: E_GOV_Index
A2: EGY_2024 | B2: EGY | C2: Egypt, Arab Rep | D2: 2024 | E2: 95 | F2: 0.70016 | G2: 0.69456 | H2: 0.61503 | I2: 0.589 | J2: 74 | K2: 0.66991667
A3: EGY_2022 | B3: EGY | C3: Egypt, Arab Rep | D3: 2022 | E3: 103 | F3: 0.573 | G3: 0.5579 | H3: 0.6375 | I3: 0.3523 | J3: 107 | K3: 0.58946667
A4: EGY_2020 | B4: EGY | C4: Egypt, Arab Rep | D4: 2020 | E4: 111 | F4: 0.5706 | G4: 0.4683 | H4: 0.6192 | I4: 0.5119 | J4: 106 | K4: 0.5527
A5: EGY_2018 | B5: EGY | C5: Egypt, Arab Rep | D5: 2018 | E5: 114 | F5: 0.5347 | G5: 0.3222 | H5: 0.6072 | I5: 0.5393 | J5: 109 | K5: 0.48803333
A6: EGY_2016 | B6: EGY | C6: Egypt, Arab Rep | D6: 2016 | E6: 108 | F6: 0.47101 | G6: 0.30246 | H6: 0.60476 | I6: 0.40678 | J6: 107 | K6: 0.45941
A7: IND_2024 | B7: IND | C7: India | D7: 2024 | E7: 97 | F7: 0.81842 | G7: 0.57004 | H7: 0.61487 | I7: 0.6575 | J7: 61 | K7: 0.66777667
A8: IND_2022 | B8: IND | C8: India | D8: 2022 | E8: 105 | F8: 0.7934 | G8: 0.3954 | H8: 0.5761 | I8: 0.5909 | J8: 61 | K8: 0.5883
A9: IND_2020 | B9: IND | C9: India | D9: 2020 | E9: 100 | F9: 0.8529 | G9: 0.3515 | H9: 0.5848 | I9: 0.8571 | J9: 29 | K9: 0.5964
A10: IND_2018 | B10: IND | C10: India | D10: 2018 | E10: 96 | F10: 0.9514 | G10: 0.2009 | H10: 0.5484 | I10: 0.9551 | J10: 15 | K10: 0.5669
A11: IND_2016 | B11: IND | C11: India | D11: 2016 | E11: 107 | F11: 0.74638 | G11: 0.14298 | H11: 0.50189 | I11: 0.76271 | J11: 27 | K11: 0.46375
A12: SAU_2024 | B12: SAU | C12: Saudi Arabia | D12: 2024 | E12: 6 | F12: 0.98995 | G12: 0.98411 | H12: 0.90666 | I12: 0.9589 | J12: 7 | K12: 0.96024
A13: SAU_2022 | B13: SAU | C13: Saudi Arabia | D13: 2022 | E13: 31 | F13: 0.822 | G13: 0.8735 | H13: 0.8662 | I13: 0.6932 | J13: 43 | K13: 0.8539
... A26: GBR_2016 | B26: GBR | C26: United Kingdom | D26: 2016 | E26: 1 | F26: 1 | G26: 0.81766 | H26: 0.94018 | I26: 1 | J26: 1 | K26: 0.91928

Sheet Internet_Index_Data_Cleaned1
A1: Code_ID | B1: Country_Code | C1: Country | D1: Year | E1: Access_Index | F1: Affordability_Index | G1: Quality_Index | H1: Internet_Index
A2: EGY_2015 | B2: EGY | C2: Egypt, Arab Rep | D2: 2015 | E2: 0.16126787 | F2: 0.63104284 | H2: 0.39615536
A3: SAU_2019 | B3: SAU | C3: Saudi Arabia | D3: 2019 | E3: 0.62501754 | F3: 0.80625401 | G3: 0.093360433 | H3: 0.50821066
A4: SAU_2015 | B4: SAU | C4: Saudi Arabia | D4: 2015 | E4: 0.42887841 | F4: 0.79494048 | H4: 0.61190945
A5: SAU_2020 | B5: SAU | C5: Saudi Arabia | D5: 2020 | E5: 0.69565987 | F5: 0.67317733 | G5: 0.24491342 | H5: 0.53791687
A6: SAU_2016 | B6: SAU | C6: Saudi Arabia | D6: 2016 | E6: 0.44257539 | F6: 0.87249184 | H6: 0.65753362
A7: SAU_2021 | B7: SAU | C7: Saudi Arabia | D7: 2021 | E7: 0.77887701 | F7: 0.57805622 | G7: 0.3194994 | H7: 0.55881088
A8: EGY_2016 | B8: EGY | C8: Egypt, Arab Rep | D8: 2016 | E8: 0.18249398 | F8: 0.76098947 | H8: 0.47174173
A9: SAU_2022 | B9: SAU | C9: Saudi Arabia | D9: 2022 | E9: 0.84988537 | F9: 0.48788688 | G9: 0.34424407 | H9: 0.56067211
A10: SAU_2017 | B10: SAU | C10: Saudi Arabia | D10: 2017 | E10: 0.55801265 | F10: 0.76550583 | H10: 0.66175924
A11: SAU_2023 | B11: SAU | C11: Saudi Arabia | D11: 2023 | E11: 0.90307143 | F11: 0.67802175 | G11: 0.36134486 | H11: 0.64747935
A12: SAU_2018 | B12: SAU | C12: Saudi Arabia | D12: 2018 | E12: 0.60680817 | F12: 0.80625401 | H12: 0.70653109
A13: SAU_2024 | B13: SAU | C13: Saudi Arabia | D13: 2024 | E13: 0.92829314 | F13: 0.92843244 | G13: 0.39789567 | H13: 0.75154042
A14: EGY_2017 | B14: EGY | C14: Egypt, Arab Rep | D14: 2017 | E14: 0.20666909 | F14: 0.86581462 | H14: 0.53624185
A15: IND_2019 | B15: IND | C15: India | D15: 2019 | E15: 0.12153213 | F15: 0.63735352 | G15: 0.035520131 | H15: 0.26480193
A16: IND_2020 | B16: IND | C16: India | D16: 2020 | E16: 0.18714871 | F16: 0.52288801 | G16: 0.069255422 | H16: 0.25976405
A17: EGY_2018 | B17: EGY | C17: Egypt, Arab Rep | D17: 2018 | E17: 0.22934967 | F17: 0.61731154 | H17: 0.42333061
A18: EGY_2019 | B18: EGY | C18: Egypt, Arab Rep | D18: 2019 | E18: 0.28513627 | F18: 0.61731154 | G18: 0.0066798628 | H18: 0.30304256
A19: EGY_2020 | B19: EGY | C19: Egypt, Arab Rep | D19: 2020 | E19: 0.36362809 | F19: 0.59955209 | G19: 0.023220114 | H19: 0.3288001
A20: EGY_2021 | B20: EGY | C20: Egypt, Arab Rep | D20: 2021 | E20: 0.37345019 | F20: 0.6130747 | G20: 0.033979383 | H20: 0.34016809
A21: EGY_2022 | B21: EGY | C21: Egypt, Arab Rep | D21: 2022 | E21: 0.38753152 | F21: 0.64246725 | G21: 0.036819293 | H21: 0.35560602
A22: EGY_2023 | B22: EGY | C22: Egypt, Arab Rep | D22: 2023 | E22: 0.39983578 | F22: 0.70078574 | G22: 0.046744579 | H22: 0.38245537
A23: EGY_2024 | B23: EGY | C23: Egypt, Arab Rep | D23: 2024 | E23: 0.42545458 | F23: 0.71060744 | G23: 0.062216847 | H23: 0.39942629
A24: IND_2015 | B24: IND | C24: India | D24: 2015 | E24: 0 | F24: 0.14207021 | H24: 0.071035104
A25: GBR_2015 | B25: GBR | C25: United Kingdom | D25: 2015 | E25: 0.70196602 | F25: 0.96459505 | H25: 0.83328054
A26: IND_2016 | B26: IND | C26: India | D26: 2016 | E26: 0.019298221 | F26: 0.13649602 | H26: 0.077897119
A27: GBR_2016 | B27: GBR | C27: United Kingdom | D27: 2016 | E27: 0.71790963 | F27: 0.98194323 | H27: 0.84992643
A28: IND_2017 | B28: IND | C28: India | D28: 2017 | E28: 0.041052588 | F28: 0.064594265 | H28: 0.052823426
A29: GBR_2019 | B29: GBR | C29: United Kingdom | D29: 2019 | E29: 0.75742641 | F29: 0.8554698 | G29: 0.11567314 | H29: 0.57618978
A30: GBR_2017 | B30: GBR | C30: United Kingdom | D30: 2017 | E30: 0.71336343 | F30: 0.89759309 | H30: 0.80547826
A31: IND_2018 | B31: IND | C31: India | D31: 2018 | E31: 0.068116664 | F31: 0.63049231 | H31: 0.34930449
A32: GBR_2018 | B32: GBR | C32: United Kingdom | D32: 2018 | E32: 0.73962884 | F32: 0.86619429 | H32: 0.80291156
A33: GBR_2020 | B33: GBR | C33: United Kingdom | D33: 2020 | E33: 0.77705178 | F33: 0.78692744 | G33: 0.14835553 | H33: 0.57077825
A34: IND_2021 | B34: IND | C34: India | D34: 2021 | E34: 0.21653733 | F34: 0.57675243 | G34: 0.11665089 | H34: 0.30331355
A35: GBR_2021 | B35: GBR | C35: United Kingdom | D35: 2021 | E35: 0.81470211 | F35: 0.88137903 | G35: 0.2326761 | H35: 0.64291908
A36: IND_2022 | B36: IND | C36: India | D36: 2022 | E36: 0.24904889 | F36: 0.62886795 | G36: 0.14009948 | H36: 0.33933878
A37: GBR_2022 | B37: GBR | C37: United Kingdom | D37: 2022 | E37: 0.81976665 | F37: 0.89883675 | G37: 0.30431665 | H37: 0.67430668
A38: IND_2023 | B38: IND | C38: India | D38: 2023 | E38: 0.27622618 | F38: 0.62471784 | G38: 0.33056899 | H38: 0.41050434
A39: GBR_2023 | B39: GBR | C39: United Kingdom | D39: 2023 | E39: 0.82596518 | F39: 0.91280902 | G39: 0.37310242 | H39: 0.70395887
A40: IND_2024 | B40: IND | C40: India | D40: 2024 | E40: 0.299587 | F40: 0.65556437 | G40: 0.34083732 | H40: 0.43199623
...
